Workbook

Sheet Dashboard
A1: SaaS Revenue Dashboard
A5: Subscription Revenue & Customer Churn Analysis
J37: Analysis Date: June 2026

Sheet Subscriptions
A1: Customer_id | B1: Plan_type | C1: Monthly_Price | D1: Start_Date | E1: End_Date
A2: C001 | B2: Basic | C2: 49 | D2: 45292
A3: C002 | B3: Pro | C3: 149 | D3: 45296 | E3: 45448
A4: C003 | B4: Basic | C4: 49 | D4: 45301
A5: C004 | B5: Enterprise | C5: 299 | D5: 45306
A6: C005 | B6: Pro | C6: 149 | D6: 45311 | E6: 45493
A7: C006 | B7: Basic | C7: 49 | D7: 45323
A8: C007 | B8: Pro | C8: 149 | D8: 45327
A9: C008 | B9: Basic | C9: 49 | D9: 45332 | E9: 45514
A10: C009 | B10: Enterprise | C10: 299 | D10: 45337
A11: C010 | B11: Pro | C11: 149 | D11: 45342
A12: C011 | B12: Basic | C12: 49 | D12: 45352
A13: C012 | B13: Pro | C13: 149 | D13: 45356 | E13: 45540
A14: C013 | B14: Enterprise | C14: 299 | D14: 45361
A15: C014 | B15: Basic | C15: 49 | D15: 45366
A16: C015 | B16: Pro | C16: 149 | D16: 45371 | E16: 45585
A17: C016 | B17: Basic | C17: 49 | D17: 45383
A18: C017 | B18: Pro | C18: 149 | D18: 45387
A19: C018 | B19: Enterprise | C19: 299 | D19: 45392 | E19: 45636
A20: C019 | B20: Basic | C20: 49 | D20: 45397
A21: C020 | B21: Pro | C21: 149 | D21: 45402
A22: C021 | B22: Basic | C22: 49 | D22: 45413
A23: C022 | B23: Pro | C23: 149 | D23: 45417 | E23: 45601
A24: C023 | B24: Enterprise | C24: 299 | D24: 45422
A25: C024 | B25: Basic | C25: 49 | D25: 45427
A26: C025 | B26: Pro | C26: 149 | D26: 45432
A27: C026 | B27: Basic | C27: 49 | D27: 45444
A28: C027 | B28: Pro | C28: 149 | D28: 45448 | E28: 45631
A29: C028 | B29: Enterprise | C29: 299 | D29: 45453
A30: C029 | B30: Basic | C30: 49 | D30: 45458
A31: C030 | B31: Pro | C31: 149 | D31: 45463
A32: C031 | B32: Basic | C32: 49 | D32: 45474
A33: C032 | B33: Pro | C33: 149 | D33: 45478
A34: C033 | B34: Enterprise | C34: 299 | D34: 45483
A35: C034 | B35: Basic | C35: 49 | D35: 45488 | E35: 45672
A36: C035 | B36: Pro | C36: 149 | D36: 45493
A37: C036 | B37: Basic | C37: 49 | D37: 45505
A38: C037 | B38: Pro | C38: 149 | D38: 45509 | E38: 45693
A39: C038 | B39: Enterprise | C39: 299 | D39: 45514
A40: C039 | B40: Basic | C40: 49 | D40: 45519
...

Sheet Insights
A1: SaaS Revenue Analysis – Insights
A3: Executive Summary
A4: This analysis evaluates SaaS revenue performance and customer churn behavior.
A6: Key Insights
A7: - The Enterprise segment generates the highest revenue
A8: - The SMB segment shows a higher churn rate
A9: - Certain acquisition channels bring lower-value customers
A11: Recommendations
A12: - Focus on Enterprise upselling strategy
A13: - Improve onboarding for SMB customers
A14: - Optimize marketing channels with low performance
A16: The relatively high churn rate suggests a need for improved customer retention strategies, particularly in the SMB segment.

Sheet Customer
A1: Customer_id | B1: Signup_date | C1: Country | D1: Acquisition_Channel | E1: segment
A2: C001 | B2: 45293 | C2: US | D2: Google Ads | E2: SMB
A3: C002 | B3: 45294 | C3: UK | D3: Organic | E3: Mid-Market
A4: C003 | B4: 45296 | C4: Canada | D4: LinkedIn Ads | E4: Enterprise
A5: C004 | B5: 45296 | C5: US | D5: Google Ads | E5: SMB
A6: C005 | B6: 45298 | C6: US | D6: Organic | E6: SMB
A7: C006 | B7: 45300 | C7: UK | D7: Google Ads | E7: Mid-Market
A8: C007 | B8: 45301 | C8: Canada | D8: LinkedIn Ads | E8: Enterprise
A9: C008 | B9: 45303 | C9: US | D9: Organic | E9: SMB
A10: C009 | B10: 45305 | C10: UK | D10: Google Ads | E10: Mid-Market
A11: C010 | B11: 45306 | C11: Canada | D11: Google Ads | E11: Mid-Market
A12: C011 | B12: 45309 | C12: US | D12: LinkedIn Ads | E12: Enterprise
A13: C012 | B13: 45310 | C13: US | D13: Organic | E13: SMB
... A51: C050 | B51: 45380 | C51: US | D51: Google Ads | E51: SMB

Sheet Customer Status
A3: Row Labels | B3: Count of Status
A4: Active | B4: 39
A5: Churned | B5: 11
A6: Grand Total | B6: 50

Sheet analysis
A1: Customer_id | B1: Segment | C1: Channel | D1: Monthly_Price | E1: Status
A2: C001 | B2: =VLOOKUP(A2, Customer!A:E, 5, FALSE) -> SMB | C2: =VLOOKUP(A2,Customer!$A$1:$E$51,4,FALSE) -> Google Ads | D2: =VLOOKUP(A2,Subscriptions!$A$1:$E$51,3,FALSE) -> 49 | E2: =IF(VLOOKUP(A2,Subscriptions!$A$1:$E$51,5,FALSE)="","Active","Churned") -> Active
A3: C002 | B3: =VLOOKUP(A3, Customer!A:E, 5, FALSE) -> Mid-Market | C3: =VLOOKUP(A3,Customer!$A$1:$E$51,4,FALSE) -> Organic | D3: =VLOOKUP(A3,Subscriptions!$A$1:$E$51,3,FALSE) -> 149 | E3: =IF(VLOOKUP(A3,Subscriptions!$A$1:$E$51,5,FALSE)="","Active","Churned") -> Churned | G3: MRR (Monthly Recurring Revenue) | H3: CHURN RATE | I3: Total Active Customers
A4: C003 | B4: =VLOOKUP(A4, Customer!A:E, 5, FALSE) -> Enterprise | C4: =VLOOKUP(A4,Customer!$A$1:$E$51,4,FALSE) -> LinkedIn Ads | D4: =VLOOKUP(A4,Subscriptions!$A$1:$E$51,3,FALSE) -> 49 | E4: =IF(VLOOKUP(A4,Subscriptions!$A$1:$E$51,5,FALSE)="","Active","Churned") -> Active | G4: =SUMIFS(D:D,E:E,"Active") -> 5461 | H4: =COUNTIF(E2:E51,"Churned")/COUNTA(A2:A51) -> 0.22 | I4: =COUNTIF(E:E,"Active") -> 39
A5: C004 | B5: =VLOOKUP(A5, Customer!A:E, 5, FALSE) -> SMB | C5: =VLOOKUP(A5,Customer!$A$1:$E$51,4,FALSE) -> Google Ads | D5: =VLOOKUP(A5,Subscriptions!$A$1:$E$51,3,FALSE) -> 299 | E5: =IF(VLOOKUP(A5,Subscriptions!$A$1:$E$51,5,FALSE)="","Active","Churned") -> Active
A6: C005 | B6: =VLOOKUP(A6, Customer!A:E, 5, FALSE) -> SMB | C6: =VLOOKUP(A6,Customer!$A$1:$E$51,4,FALSE) -> Organic | D6: =VLOOKUP(A6,Subscriptions!$A$1:$E$51,3,FALSE) -> 149 | E6: =IF(VLOOKUP(A6,Subscriptions!$A$1:$E$51,5,FALSE)="","Active","Churned") -> Churned
A7: C006 | B7: =VLOOKUP(A7, Customer!A:E, 5, FALSE) -> Mid-Market | C7: =VLOOKUP(A7,Customer!$A$1:$E$51,4,FALSE) -> Google Ads | D7: =VLOOKUP(A7,Subscriptions!$A$1:$E$51,3,FALSE) -> 49 | E7: =IF(VLOOKUP(A7,Subscriptions!$A$1:$E$51,5,FALSE)="","Active","Churned") -> Active
A8: C007 | B8: =VLOOKUP(A8, Customer!A:E, 5, FALSE) -> Enterprise | C8: =VLOOKUP(A8,Customer!$A$1:$E$51,4,FALSE) -> LinkedIn Ads | D8: =VLOOKUP(A8,Subscriptions!$A$1:$E$51,3,FALSE) -> 149 | E8: =IF(VLOOKUP(A8,Subscriptions!$A$1:$E$51,5,FALSE)="","Active","Churned") -> Active
A9: C008 | B9: =VLOOKUP(A9, Customer!A:E, 5, FALSE) -> SMB | C9: =VLOOKUP(A9,Customer!$A$1:$E$51,4,FALSE) -> Organic | D9: =VLOOKUP(A9,Subscriptions!$A$1:$E$51,3,FALSE) -> 49 | E9: =IF(VLOOKUP(A9,Subscriptions!$A$1:$E$51,5,FALSE)="","Active","Churned") -> Churned
A10: C009 | B10: =VLOOKUP(A10, Customer!A:E, 5, FALSE) -> Mid-Market | C10: =VLOOKUP(A10,Customer!$A$1:$E$51,4,FALSE) -> Google Ads | D10: =VLOOKUP(A10,Subscriptions!$A$1:$E$51,3,FALSE) -> 299 | E10: =IF(VLOOKUP(A10,Subscriptions!$A$1:$E$51,5,FALSE)="","Active","Churned") -> Active
A11: C010 | B11: =VLOOKUP(A11, Customer!A:E, 5, FALSE) -> Mid-Market | C11: =VLOOKUP(A11,Customer!$A$1:$E$51,4,FALSE) -> Google Ads | D11: =VLOOKUP(A11,Subscriptions!$A$1:$E$51,3,FALSE) -> 149 | E11: =IF(VLOOKUP(A11,Subscriptions!$A$1:$E$51,5,FALSE)="","Active","Churned") -> Active
A12: C011 | B12: =VLOOKUP(A12, Customer!A:E, 5, FALSE) -> Enterprise | C12: =VLOOKUP(A12,Customer!$A$1:$E$51,4,FALSE) -> LinkedIn Ads | D12: =VLOOKUP(A12,Subscriptions!$A$1:$E$51,3,FALSE) -> 49 | E12: =IF(VLOOKUP(A12,Subscriptions!$A$1:$E$51,5,FALSE)="","Active","Churned") -> Active
A13: C012 | B13: =VLOOKUP(A13, Customer!A:E, 5, FALSE) -> SMB | C13: =VLOOKUP(A13,Customer!$A$1:$E$51,4,FALSE) -> Organic | D13: =VLOOKUP(A13,Subscriptions!$A$1:$E$51,3,FALSE) -> 149 | E13: =IF(VLOOKUP(A13,Subscriptions!$A$1:$E$51,5,FALSE)="","Active","Churned") -> Churned
A14: C013 | B14: =VLOOKUP(A14, Customer!A:E, 5, FALSE) -> Mid-Market | C14: =VLOOKUP(A14,Customer!$A$1:$E$51,4,FALSE) -> Google Ads | D14: =VLOOKUP(A14,Subscriptions!$A$1:$E$51,3,FALSE) -> 299 | E14: =IF(VLOOKUP(A14,Subscriptions!$A$1:$E$51,5,FALSE)="","Active","Churned") -> Active
A15: C014 | B15: =VLOOKUP(A15, Customer!A:E, 5, FALSE) -> Enterprise | C15: =VLOOKUP(A15,Customer!$A$1:$E$51,4,FALSE) -> LinkedIn Ads | D15: =VLOOKUP(A15,Subscriptions!$A$1:$E$51,3,FALSE) -> 49 | E15: =IF(VLOOKUP(A15,Subscriptions!$A$1:$E$51,5,FALSE)="","Active","Churned") -> Active
A16: C015 | B16: =VLOOKUP(A16, Customer!A:E, 5, FALSE) -> SMB | C16: =VLOOKUP(A16,Customer!$A$1:$E$51,4,FALSE) -> Google Ads | D16: =VLOOKUP(A16,Subscriptions!$A$1:$E$51,3,FALSE) -> 149 | E16: =IF(VLOOKUP(A16,Subscriptions!$A$1:$E$51,5,FALSE)="","Active","Churned") -> Churned
... A51: C050 | B51: =VLOOKUP(A51, Customer!A:E, 5, FALSE) -> SMB | C51: =VLOOKUP(A51,Customer!$A$1:$E$51,4,FALSE) -> Google Ads | D51: =VLOOKUP(A51,Subscriptions!$A$1:$E$51,3,FALSE) -> 149 | E51: =IF(VLOOKUP(A51,Subscriptions!$A$1:$E$51,5,FALSE)="","Active","Churned") -> Active

Sheet Revenue by Segment
A3: Row Labels | B3: Sum of Monthly_Price
A4: Enterprise | B4: 1785
A5: SMB | B5: 2532
A6: Mid-Market | B6: 2633

Sheet Revenue by Channel
A3: Row Labels | B3: Sum of Monthly_Price
A4: Google Ads | B4: 3380
A5: LinkedIn Ads | B5: 1635
A6: Organic | B6: 1935
