Workbook

Sheet Customers
A1: customer_id | B1: segment | C1: country | D1: acquisition_channel | E1: signup_date
A2: C001 | B2: Startup | C2: Indonesia | D2: Google Ads | E2: 45660
A3: C002 | B3: Startup | C3: Indonesia | D3: Google Ads | E3: 45662
A4: C003 | B4: Startup | C4: Indonesia | D4: Google Ads | E4: 45664
A5: C004 | B5: Startup | C5: Indonesia | D5: Google Ads | E5: 45667
A6: C005 | B6: Startup | C6: Indonesia | D6: Google Ads | E6: 45669
A7: C006 | B7: Startup | C7: Indonesia | D7: Google Ads | E7: 45672
A8: C007 | B8: Startup | C8: Indonesia | D8: Google Ads | E8: 45675
A9: C008 | B9: Startup | C9: Indonesia | D9: Google Ads | E9: 45679
A10: C009 | B10: Startup | C10: Indonesia | D10: Google Ads | E10: 45682
A11: C010 | B11: Startup | C11: Indonesia | D11: Google Ads | E11: 45685
A12: C011 | B12: Startup | C12: Indonesia | D12: Google Ads | E12: 45690
A13: C012 | B13: Startup | C13: Indonesia | D13: Google Ads | E13: 45693
... A151: C150 | B151: Enterprise | C151: United Kingdom | D151: Organic | E151: 45986

Sheet Revenue by Segment
A3: Row Labels | B3: Sum of mrr
A4: Basic | B4: 3675
A5: Enterprise | B5: 12475
A6: Pro | B6: 7450
A7: Grand Total | B7: 23600

Sheet Active VS Churned
A3: Row Labels | B3: Count of customer_id
A4: Active | B4: 120
A5: Churned | B5: 30
A6: Grand Total | B6: 150

Sheet Subscriptions
A1: customer_id | B1: plan | C1: mrr | D1: status | E1: start_date | F1: end_date
A2: C001 | B2: Basic | C2: 49 | D2: Active | E2: =Customers!E2 -> 45660
A3: C002 | B3: Basic | C3: 49 | D3: Active | E3: =Customers!E3 -> 45662
A4: C003 | B4: Basic | C4: 49 | D4: Active | E4: =Customers!E4 -> 45664
A5: C004 | B5: Basic | C5: 49 | D5: Active | E5: =Customers!E5 -> 45667
A6: C005 | B6: Basic | C6: 49 | D6: Churned | E6: =Customers!E6 -> 45669 | F6: 45759
A7: C006 | B7: Basic | C7: 49 | D7: Active | E7: =Customers!E7 -> 45672
A8: C007 | B8: Basic | C8: 49 | D8: Active | E8: =Customers!E8 -> 45675
A9: C008 | B9: Basic | C9: 49 | D9: Active | E9: =Customers!E9 -> 45679
A10: C009 | B10: Basic | C10: 49 | D10: Active | E10: =Customers!E10 -> 45682
A11: C010 | B11: Basic | C11: 49 | D11: Churned | E11: =Customers!E11 -> 45685 | F11: 45774
A12: C011 | B12: Basic | C12: 49 | D12: Active | E12: =Customers!E12 -> 45690
A13: C012 | B13: Basic | C13: 49 | D13: Active | E13: =Customers!E13 -> 45693
A14: C013 | B14: Basic | C14: 49 | D14: Active | E14: =Customers!E14 -> 45696
A15: C014 | B15: Basic | C15: 49 | D15: Active | E15: =Customers!E15 -> 45698
A16: C015 | B16: Basic | C16: 49 | D16: Churned | E16: =Customers!E16 -> 45701 | F16: 45780
A17: C016 | B17: Basic | C17: 49 | D17: Active | E17: =Customers!E17 -> 45704
A18: C017 | B18: Basic | C18: 49 | D18: Active | E18: =Customers!E18 -> 45706
A19: C018 | B19: Basic | C19: 49 | D19: Active | E19: =Customers!E19 -> 45709
A20: C019 | B20: Basic | C20: 49 | D20: Active | E20: =Customers!E20 -> 45712
A21: C020 | B21: Basic | C21: 49 | D21: Churned | E21: =Customers!E21 -> 45715 | F21: 45795
A22: C021 | B22: Basic | C22: 49 | D22: Active | E22: =Customers!E22 -> 45718
A23: C022 | B23: Basic | C23: 49 | D23: Active | E23: =Customers!E23 -> 45720
A24: C023 | B24: Basic | C24: 49 | D24: Active | E24: =Customers!E24 -> 45722
A25: C024 | B25: Basic | C25: 49 | D25: Active | E25: =Customers!E25 -> 45724
A26: C025 | B26: Basic | C26: 49 | D26: Churned | E26: =Customers!E26 -> 45726 | F26: 45795
A27: C026 | B27: Basic | C27: 49 | D27: Active | E27: =Customers!E27 -> 45728
A28: C027 | B28: Basic | C28: 49 | D28: Active | E28: =Customers!E28 -> 45730
A29: C028 | B29: Basic | C29: 49 | D29: Active | E29: =Customers!E29 -> 45732
A30: C029 | B30: Basic | C30: 49 | D30: Active | E30: =Customers!E30 -> 45734
A31: C030 | B31: Basic | C31: 49 | D31: Churned | E31: =Customers!E31 -> 45736 | F31: 45806
A32: C031 | B32: Basic | C32: 49 | D32: Active | E32: =Customers!E32 -> 45740
A33: C032 | B33: Basic | C33: 49 | D33: Active | E33: =Customers!E33 -> 45744
A34: C033 | B34: Basic | C34: 49 | D34: Active | E34: =Customers!E34 -> 45749
A35: C034 | B35: Basic | C35: 49 | D35: Active | E35: =Customers!E35 -> 45751
A36: C035 | B36: Basic | C36: 49 | D36: Churned | E36: =Customers!E36 -> 45753 | F36: 45815
A37: C036 | B37: Basic | C37: 49 | D37: Active | E37: =Customers!E37 -> 45755
A38: C037 | B38: Basic | C38: 49 | D38: Active | E38: =Customers!E38 -> 45757
A39: C038 | B39: Basic | C39: 49 | D39: Active | E39: =Customers!E39 -> 45759
A40: C039 | B40: Basic | C40: 49 | D40: Active | E40: =Customers!E40 -> 45761
...

Sheet CAC by Channel
A3: Row Labels | B3: Average of CAC
A4: Facebook Ads | B4: 43.237902
A5: Google Ads | B5: 49.931582
A6: LinkedIn Ads | B6: 90.717864
A7: Organic | B7: 9.2668732
A8: Referral | B8: 20.002769
A9: Grand Total | B9: 42.631398

Sheet Signups by Channel
A3: Row Labels | B3: Sum of signups
A4: Facebook Ads | B4: 1125
A5: Google Ads | B5: 1466
A6: LinkedIn Ads | B6: 674
A7: Organic | B7: 823
A8: Referral | B8: 885
A9: Grand Total | B9: 4973

Sheet Marketing_Spend
A1: month | B1: channel | C1: spend | D1: signups | E1: CAC
A2: 45658 | B2: Google Ads | C2: 5000 | D2: 100 | E2: =C2/D2 -> 50
A3: 45658 | B3: Facebook Ads | C3: 3500 | D3: 80 | E3: =C3/D3 -> 43.75
A4: 45658 | B4: LinkedIn Ads | C4: 4500 | D4: 45 | E4: =C4/D4 -> 100
A5: 45658 | B5: Referral | C5: 1200 | D5: 60 | E5: =C5/D5 -> 20
A6: 45658 | B6: Organic | C6: 500 | D6: 55 | E6: =C6/D6 -> 9.0909091
A7: 45689 | B7: Google Ads | C7: 5200 | D7: 105 | E7: =C7/D7 -> 49.52381
A8: 45689 | B8: Facebook Ads | C8: 3600 | D8: 82 | E8: =C8/D8 -> 43.902439
A9: 45689 | B9: LinkedIn Ads | C9: 4600 | D9: 47 | E9: =C9/D9 -> 97.87234
A10: 45689 | B10: Referral | C10: 1250 | D10: 62 | E10: =C10/D10 -> 20.16129
A11: 45689 | B11: Organic | C11: 520 | D11: 58 | E11: =C11/D11 -> 8.9655172
A12: 45717 | B12: Google Ads | C12: 5400 | D12: 108 | E12: =C12/D12 -> 50
A13: 45717 | B13: Facebook Ads | C13: 3700 | D13: 85 | E13: =C13/D13 -> 43.529412
... A61: 45992 | B61: Organic | C61: 780 | D61: 82 | E61: =C61/D61 -> 9.5121951

Sheet Revenue Summary
A1: Month | B1: Revenue
A2: 45682 | B2: 5500
A3: 45713 | B3: 6300
A4: 45741 | B4: 7400
A5: 45772 | B5: 8500
A6: 45802 | B6: 9800
A7: 45833 | B7: 11200
A8: 45863 | B8: 12900
A9: 45894 | B9: 14700
A10: 45925 | B10: 16800
A11: 45955 | B11: 19000
A12: 45986 | B12: 21500
A13: 46016 | B13: 24000

Sheet KPI_Calculations
A1: KPI | B1: Value
A2: Total Customers | B2: =COUNTA(Customers!A2:A151) -> 150
A3: Active Customers | B3: =COUNTIF(Subscriptions!D:D, "Active") -> 120
A4: Churned Customers | B4: =COUNTIF(Subscriptions!D:D, "Churned") -> 30
A5: Churn Rate | B5: =B4/B2 -> 0.2
A6: Average CAC | B6: =AVERAGE(Marketing_Spend!E:E) -> 42.631398
A7: Total MRR | B7: =SUM(Subscriptions!C:C) -> 23600
A8: ARPU (Average Revenue Per User) | B8: =B7/B2 -> 157.33333
A9: Average Lifetime | B9: =1/B5 -> 5
A10: LTV (Lifetime Value) | B10: =B8*B9 -> 786.66667
A11: LTV/CAC Ratio | B11: =B10/B6 -> 18.452753
